<?xml version="1.0" ?>
<robot name="urdf_robot">
    <material name="finger_base_material">
        <color rgba="0.8 0.8 0.8 1"/>
    </material>
    <material name="finger_material">
        <color rgba="1 0.5 0.5 1"/>
    </material>
    <material name="wrist_material">
        <color rgba="0 0 0 1"/>
    </material>
    <contact name="gripper_contact">
        <rolling_friction value="0.1"/>
        <spinning_friction value="0.1"/>
    </contact>

    <link name="base">
        <inertial>
            <origin rpy="0 0 0" xyz="0 0 0"/>
            <mass value="0"/>
            <inertia ixx="0" ixy="0" ixz="0" iyy="0" iyz="0" izz="0"/>
        </inertial>
    </link>

    <joint name="hand_slider_x" type="prismatic">
        <parent link="base"/>
        <child link="dummy1"/>
        <axis xyz="1 0 0"/>
        <limit lower="-0.4" upper="0.4" />
        <origin rpy="0 0 0" xyz="0.0 0.0 0.1"/>
    </joint>
    <link name="dummy1">
        <inertial>
            <origin rpy="0 0 0" xyz="0 0.1 0.15"/>
            <mass value="0"/>
            <inertia ixx="0" ixy="0" ixz="0" iyy="0" iyz="0" izz="0"/>
        </inertial>
    </link>

    <joint name="hand_slider_y" type="prismatic">
        <parent link="dummy1"/>
        <child link="dummy2"/>
        <axis xyz="0 1 0"/>
        <limit lower="-0.4" upper="0.4" />
    </joint>
    <link name="dummy2">
        <inertial>
            <origin rpy="0 0 0" xyz="0 0.1 0.15"/>
            <mass value="0"/>
            <inertia ixx="0" ixy="0" ixz="0" iyy="0" iyz="0" izz="0"/>
        </inertial>
    </link>

    <joint name="hand_slider_z" type="prismatic">
        <parent link="dummy2"/>
        <child link="dummy3"/>
        <axis xyz="0 0 1"/>
        <limit lower="0" upper="0.8" />
    </joint>
    <link name="dummy3">
        <inertial>
            <origin rpy="0 0 0" xyz="0 0.1 0.15"/>
            <mass value="0"/>
            <inertia ixx="0" ixy="0" ixz="0" iyy="0" iyz="0" izz="0"/>
        </inertial>
    </link>

    <joint name="hand_rotation_y" type="revolute">
        <parent link="dummy3"/>
        <child link="wrist"/>
        <axis xyz="0 1 0"/>
	    <limit lower="0" upper="3.14"/>
        <origin rpy="0 0 0" xyz="0.0 -0.1 0"/>
    </joint>
    <link name="wrist">
        <inertial>
            <origin rpy="0 0 0" xyz="0 0 0"/>
            <mass value="1"/>
            <inertia ixx="1" ixy="0" ixz="0" iyy="1" iyz="0" izz="1"/>
        </inertial>
        <visual>
            <origin rpy="0 0 0" xyz="0.0 0 0"/>
            <geometry>
                <box size="0.05 0.05 0.05"/>
            </geometry>
            <material name="wrist_material"/>
        </visual>
        <collision>
            <origin rpy="0 0 0" xyz="0.0 0 0"/>
            <geometry>
                <box size="0.05 0.05 0.05"/>
            </geometry>
        </collision>
    </link>

    <joint name="finger_base_to_wrist" type="fixed">
        <parent link="wrist"/>
        <child link="finger_base"/>
    </joint>
    <link name="finger_base">
        <contact name="gripper_contact"/>
        <inertial>
            <origin rpy="0 0 0" xyz="0 -0.05 0"/>
            <mass value="1"/>
            <inertia ixx="1" ixy="0" ixz="0" iyy="1" iyz="0" izz="1"/>
        </inertial>
        <visual>
            <origin rpy="0 0 0" xyz="0.0 -0.05 0"/>
            <geometry>
                <box size="0.8 0.1 0.3"/>
            </geometry>
            <material name="finger_base_material"/>
        </visual>
        <collision>
            <origin rpy="0 0 0" xyz="0.0 -0.05 0"/>
            <geometry>
                <box size="0.8 0.1 0.3"/>
            </geometry>
        </collision>
    </link>

    <joint name="right_finger_slider" type="prismatic">
        <parent link="finger_base"/>
        <child link="right_finger"/>
        <axis xyz="1 0 0"/>
        <limit lower="0" upper="0.3" />
        <origin xyz="-0.35 0 0"/>
    </joint>
    <link name="right_finger">
        <contact name="gripper_contact"/>
        <inertial>
            <origin rpy="0 0 0" xyz="0 -0.4 0"/>
            <mass value="1"/>
            <inertia ixx="1" ixy="0" ixz="0" iyy="1" iyz="0" izz="1"/>
        </inertial>
        <visual>
            <origin rpy="0 0 0" xyz="0 -0.4 0"/>
            <geometry>
                <box size="0.1 0.6 0.1"/>
            </geometry>
            <material name="finger_material"/>
        </visual>
        <collision>
            <origin rpy="0 0 0" xyz="0 -0.4 0"/>
            <geometry>
                <box size="0.1 0.6 0.1"/>
            </geometry>
        </collision>
    </link>

    <joint name="left_finger_slider" type="prismatic">
        <parent link="finger_base"/>
        <child link="left_finger"/>
        <axis xyz="1 0 0"/>
        <limit lower="-0.3" upper="0" />
        <origin xyz="0.35 0 0"/>
    </joint>
    <link name="left_finger">
        <contact name="gripper_contact"/>
        <inertial>
            <origin rpy="0 0 0" xyz="0 -0.4 0"/>
            <mass value="1"/>
            <inertia ixx="1" ixy="0" ixz="0" iyy="1" iyz="0" izz="1"/>
        </inertial>
        <visual>
            <origin rpy="0 0 0" xyz="0 -0.4 0"/>
            <geometry>
                <box size="0.1 0.6 0.1"/>
            </geometry>
            <material name="finger_material"/>
        </visual>
        <collision>
            <origin rpy="0 0 0" xyz="0 -0.4 0"/>
            <geometry>
                <box size="0.1 0.6 0.1"/>
            </geometry>
        </collision>
    </link>
</robot>


